<?xml version="1.0" encoding="UTF-8"?>
<testsuite hostname="dashree-PC" name="com.urlcat.tests.client.Test_Automation_02" tests="1" failures="1" timestamp="23 Aug 2018 12:07:52 GMT" time="5.662" errors="0">
  <testcase name="updatedCategoryReceived" time="2.044" classname="com.urlcat.tests.client.Test_Automation_02">
    <failure type="java.lang.ArrayIndexOutOfBoundsException" message="23">
      <![CDATA[java.lang.ArrayIndexOutOfBoundsException: 23
	at com.urlcat.tests.client.Test_Automation_02.updatedCategoryReceived(Test_Automation_02.java:29)
	at sun.reflect.NativeMethodAccessorImpl.invoke0(Native Method)
	at sun.reflect.NativeMethodAccessorImpl.invoke(Unknown Source)
	at sun.reflect.DelegatingMethodAccessorImpl.invoke(Unknown Source)
	at java.lang.reflect.Method.invoke(Unknown Source)
	at org.testng.internal.MethodInvocationHelper.invokeMethod(MethodInvocationHelper.java:80)
	at org.testng.internal.Invoker.invokeMethod(Invoker.java:673)
	at org.testng.internal.Invoker.invokeTestMethod(Invoker.java:842)
	at org.testng.internal.Invoker.invokeTestMethods(Invoker.java:1166)
	at org.testng.internal.TestMethodWorker.invokeTestMethods(TestMethodWorker.java:125)
	at org.testng.internal.TestMethodWorker.run(TestMethodWorker.java:109)
	at org.testng.TestRunner.runWorkers(TestRunner.java:1178)
	at org.testng.TestRunner.privateRun(TestRunner.java:757)
	at org.testng.TestRunner.run(TestRunner.java:608)
	at org.testng.SuiteRunner.runTest(SuiteRunner.java:334)
	at org.testng.SuiteRunner.runSequentially(SuiteRunner.java:329)
	at org.testng.SuiteRunner.privateRun(SuiteRunner.java:291)
	at org.testng.SuiteRunner.run(SuiteRunner.java:240)
	at org.testng.SuiteRunnerWorker.runSuite(SuiteRunnerWorker.java:52)
	at org.testng.SuiteRunnerWorker.run(SuiteRunnerWorker.java:86)
	at org.testng.TestNG.runSuitesSequentially(TestNG.java:1158)
	at org.testng.TestNG.runSuitesLocally(TestNG.java:1083)
	at org.testng.TestNG.run(TestNG.java:999)
	at org.testng.remote.AbstractRemoteTestNG.run(AbstractRemoteTestNG.java:114)
	at org.testng.remote.RemoteTestNG.initAndRun(RemoteTestNG.java:251)
	at org.testng.remote.RemoteTestNG.main(RemoteTestNG.java:77)
]]>
    </failure>
  </testcase>
</testsuite>
